Workbook

Sheet Bewertung
A1: Bewertung der Datenschutzprozesse nach DSGVO
A3: Die Datenschutzbewertungstabelle vermittelt einen schnellen Überblick über den Stand des Datenschutzes im Unternehmen, denn sie zeigt in einer grafischen Übersicht
A4: den Erfüllungsgrad für jeden einzelnen Datenschutzprozess.
A5: Die Bewertungstabelle kann als Anlage zum Datenschutzbericht des Datenschutzbeauftragten an die Geschäftsleitung verwendet werden. Der Geschäftsleitung werden
A6: in einer verbindlichen Form der Stand des Datenschutzes vermittelt und eventuelle Handlungsbedarfe aufgezeigt.
A7: In einem Vergleich über einen längeren Zeitraum wird auch die Entwicklung des Datenschutzes erkennbar.
A9: Zweckmäßig ist die Abstimmung des Erfüllungsgrades der einzelnen Kriterien mit den Prozessverantwortlichen bereits bei der Erhebung bzw. den laufenden Kontrollen
A10: der Datenschutzprozesse. Auf diese Weise werden spätere Diskussionen mit den Fachverantwortlichen vermieden und die Ergebnisse der Bewertungen in der Tabelle
A11: sind belastbar. Sie können auf diese Weise sofort als Beleg- und Nachweisdokument nicht nur für die Durchführung der Erhebungen und Kontrollen, sondern auch für die
A12: Erfüllung der Datenschutzanforderungen dienen.
A13: Dies schließt natürlich nicht aus, dass der Datenschutzbeauftragte auch von der Position der Fachbereichsverantwortlichen abweichende Positionen vertritt und Maßnah-
A14: men bzw. Korrekturen der Verarbeitungsprozesse fordert. Der Vorteil dieser Vorgehensweise liegt darin, evtl. bereits abgestimmte Lösungsvorschläge aufgezeigt werden
... A36: übernommen. Diese errechnet dann für jeden Datenschutzprozess den prozentualen Erfüllungsgrad und erzeugt eine grafische Auswertung in Tabellenblatt „Grafik“.
A38: Prozess / Thema | B38: Hauptthema | C38: Zu überprüfende Maßnahme | D38: Trifft zu | E38: Erfüllungsgrad | F38: Bemerkungen | G38: Punkte Ist | H38: Punkte Soll
A39: Management- Strategien zum Datenschutz | B39: Abdeckungsgrad des Datenschutz-managements | C39: Sind Anforderungen des Datenschutzmanagements durch ein QM-System nach DIN/ISO 9000 abgedeckt? | G39: =D39*E39 -> 0 | H39: =D39*4 -> 0
C40: Sind Anforderungen des Datenschutzmanagements durch ein IT-Sicherheitsmanagementsystem (z.B. ISO/IEC 27001) abgedeckt? | G40: =D40*E40 -> 0 | H40: =D40*4 -> 0
C41: Sind Anforderungen des Datenschutzmanagements durch andere Management-/Kontrollsysteme (z.B. Internes Kontrollsystem - IKS, SOX etc.) abgedeckt? | G41: =D41*E41 -> 0 | H41: =D41*4 -> 0
B42: Datenschutzziele und Strategien | C42: Sind die Managementanforderungen des Datenschutzes (Datenschutzziele und Strategien etc.) erfüllt? | G42: =D42*E42 -> 0 | H42: =D42*4 -> 0
A43: Summe | G43: =SUM(G39:G42) -> 0 | H43: =SUM(H39:H42) -> 0
A44: Melde- und Informationspflicht bei Datenschutz-verletzungen | C44: Ist ein geregelter Prozess zur Melde- und Informationspflicht mit Festlegung der Prozessverantwortlichen eingerichtet? | G44: =D44*E44 -> 0 | H44: =D44*4 -> 0
C45: Ist die Beteiligung des betrieblichen Datenschutzbeauftragten geregelt? | G45: =D45*E45 -> 0 | H45: =D45*4 -> 0
C46: Ist ein Verfahren zur Beurteilung des Risikos für die Rechte und Freiheiten der Betroffenen geregelt, z.B. mit einem Prüf- und Dokumentationsformular? | G46: =D46*E46 -> 0 | H46: =D46*4 -> 0
C47: Ist bei Auftragsdatenverarbeitern die Meldung an den Auftraggeber geregelt? | G47: =D47*E47 -> 0 | H47: =D47*4 -> 0
C48: Sind Form, Inhalt und Verfahren der Meldung an die Aufsichtsbehörde und zur Unterrichtung der Betroffenen geregelt? | G48: =D48*E48 -> 0 | H48: =D48*4 -> 0
C49: Ist die Dokumentation von Art, Umfang, Ausmaß und Risiko der Datenschutzverletzung geregelt? | G49: =D49*E49 -> 0 | H49: =D49*4 -> 0
C50: Ist ein Verfahren zur Beurteilung der Informations-pflicht an die Betroffenen eingerichtet? | G50: =D50*E50 -> 0 | H50: =D50*4 -> 0
C51: Ist ein Verfahren zur sicherheitstechnischen Behandlung der Vorfälle (Analyse, Fehler-beseitigung, Vorbeugungsmaßnahmen und Dokumentation) eingerichtet? | G51: =D51*E51 -> 0 | H51: =D51*4 -> 0
A52: Summe | G52: =SUM(G44:G51) -> 0 | H52: =SUM(H44:H51) -> 0
A53: Bestellung eines Datenschutz-beauftragten | B53: Bestellung prüfen | C53: Ist die Bestellpflicht eines Datenschutzbeauftragten geprüft und entschieden? | G53: =D53*E53 -> 0 | H53: =D53*4 -> 0
C54: Ist ein Datenschutzbeauftragter bestellt? | G54: =D54*E54 -> 0 | H54: =D54*4 -> 0
C55: Ist im Falle einer Nichtbestellung die Wahrnehmung der Datenschutzaufgaben auf andere Weise gewährleistet? | G55: =D55*E55 -> 0 | H55: =D55*4 -> 0
C56: Sind die Rechte, Unabhängigkeit und Weisungsfreiheit des Datenschutzbeauftragten geregelt und gewährleistet? | G56: =D56*E56 -> 0 | H56: =D56*4 -> 0
C57: Sind die internen und externen Aufgaben des Datenschutzbeauftragten schriftlich und klar geregelt? | G57: =D57*E57 -> 0 | H57: =D57*4 -> 0
C58: Ist die organistorische Einbindung des Datenschutzbeauftragten geregelt? | G58: =D58*E58 -> 0 | H58: =D58*4 -> 0
C59: Sind die Kontaktdaten des Datenschutz-beauftragten veröffentlicht? | G59: =D59*E59 -> 0 | H59: =D59*4 -> 0
C60: Sind die Kontaktdaten des Datenschutz-beauftragten der Aufsichtsbehörde gemeldet? | G60: =D60*E60 -> 0 | H60: =D60*4 -> 0
A61: Summe | G61: =SUM(G53:G60) -> 0 | H61: =SUM(H53:H60) -> 0
A62: Übersicht über Verarbeitungs-tätigkeiten | C62: Ist die Verpflichtung zur Führung einer Übersicht über die Verarbeitungstätigkeiten geprüft und ggf. eine Übersicht über diese angelegt? | G62: =D62*E62 -> 0 | H62: =D62*4 -> 0
C63: Ist die Verantwortlichkeit für die Führung des Verzeichnisses über die Verarbeitungstätigkeiten geregelt? | G63: =D63*E63 -> 0 | H63: =D63*4 -> 0
C64: Ist die Übersicht über die Verarbeitungstätigkeiten hinsichtlich der vorgeschriebenen Inhalte aktuell? | G64: =D64*E64 -> 0 | H64: =D64*4 -> 0
...

Sheet Erfüllungsgrad
A1: Erfüllung der rechtlichen Anforderungen der DSGVO
A2: und der eingerichteten Datenschutzprozesse
A4: Prozess / Thema | B4: Sollwert in % | C4: Istwert in % | D4: Sollwert | E4: Istwert
A5: Datenschutzmanagement, Strategien zum Datenschutz | B5: 100 | C5: =IF(ISERROR(E5*100/D5),"trifft nicht zu",(E5*100/D5)) -> trifft nicht zu | D5: =Bewertung!H43 -> 0 | E5: =Bewertung!G43 -> 0
A6: Melde- und Informationspflicht bei Datenschutzverletzungen | B6: 100 | C6: =IF(ISERROR(E6*100/D6),"trifft nicht zu",(E6*100/D6)) -> trifft nicht zu | D6: =Bewertung!H52 -> 0 | E6: =Bewertung!G52 -> 0
A7: Bestellung eines Datenschutzbeauftragten | B7: 100 | C7: =IF(ISERROR(E7*100/D7),"trifft nicht zu",(E7*100/D7)) -> trifft nicht zu | D7: =Bewertung!H61 -> 0 | E7: =Bewertung!G61 -> 0
A8: Übersicht über Verarbeitungstätigkeiten | B8: 100 | C8: =IF(ISERROR(E8*100/D8),"trifft nicht zu",(E8*100/D8)) -> trifft nicht zu | D8: =Bewertung!H67 -> 0 | E8: =Bewertung!G67 -> 0
A9: Grundsätze der Datenverarbeitung | B9: 100 | C9: =IF(ISERROR(E9*100/D9),"trifft nicht zu",(E9*100/D9)) -> trifft nicht zu | D9: =Bewertung!H76 -> 0 | E9: =Bewertung!G76 -> 0
A10: Rechtmäßigkeit der Verarbeitung | B10: 100 | C10: =IF(ISERROR(E10*100/D10),"trifft nicht zu",(E10*100/D10)) -> trifft nicht zu | D10: =Bewertung!H81 -> 0 | E10: =Bewertung!G81 -> 0
A11: Rechte der Betroffenen | B11: 100 | C11: =IF(ISERROR(E11*100/D11),"trifft nicht zu",(E11*100/D11)) -> trifft nicht zu | D11: =Bewertung!H93 -> 0 | E11: =Bewertung!G93 -> 0
A12: Verarbeitung von besonderen Datenarten | B12: 100 | C12: =IF(ISERROR(E12*100/D12),"trifft nicht zu",(E12*100/D12)) -> trifft nicht zu | D12: =Bewertung!H95 -> 0 | E12: =Bewertung!G95 -> 0
A13: Nichtidentifizierbare Personen | B13: 100 | C13: =IF(ISERROR(E13*100/D13),"trifft nicht zu",(E13*100/D13)) -> trifft nicht zu | D13: =Bewertung!H98 -> 0 | E13: =Bewertung!G98 -> 0
A14: Information der Betroffenen | B14: 100 | C14: =IF(ISERROR(E14*100/D14),"trifft nicht zu",(E14*100/D14)) -> trifft nicht zu | D14: =Bewertung!H105 -> 0 | E14: =Bewertung!G105 -> 0
A15: Automatisierte Einzelentscheidung und Profiling | B15: 100 | C15: =IF(ISERROR(E15*100/D15),"trifft nicht zu",(E15*100/D15)) -> trifft nicht zu | D15: =Bewertung!H111 -> 0 | E15: =Bewertung!G111 -> 0
A16: Gemeinsam Verantwortliche und Auftrgsdatenverarbeiter | B16: 100 | C16: =IF(ISERROR(E16*100/D16),"trifft nicht zu",(E16*100/D16)) -> trifft nicht zu | D16: =Bewertung!H119 -> 0 | E16: =Bewertung!G119 -> 0
A17: Veararbeitung von Personaldaten | B17: 100 | C17: =IF(ISERROR(E17*100/D17),"trifft nicht zu",(E17*100/D17)) -> trifft nicht zu | D17: =Bewertung!H143 -> 0 | E17: =Bewertung!G143 -> 0
A18: Nutzung von Kundendaten für Werbung | B18: 100 | C18: =IF(ISERROR(E18*100/D18),"trifft nicht zu",(E18*100/D18)) -> trifft nicht zu | D18: =Bewertung!H162 -> 0 | E18: =Bewertung!G162 -> 0
A19: Einwilligungen | B19: 100 | C19: =IF(ISERROR(E19*100/D19),"trifft nicht zu",(E19*100/D19)) -> trifft nicht zu | D19: =Bewertung!H169 -> 0 | E19: =Bewertung!G169 -> 0
A20: Scoring, Bonitätsauskünfte | B20: 100 | C20: =IF(ISERROR(E20*100/D20),"trifft nicht zu",(E20*100/D20)) -> trifft nicht zu | D20: =Bewertung!H174 -> 0 | E20: =Bewertung!G174 -> 0
A21: Datenübermittlung in Drittländer | B21: 100 | C21: =IF(ISERROR(E21*100/D21),"trifft nicht zu",(E21*100/D21)) -> trifft nicht zu | D21: =Bewertung!H180 -> 0 | E21: =Bewertung!G180 -> 0
A22: Risiko- und Schutzbedarfsermittlung Datenschutzfolgenabschätzung | B22: 100 | C22: =IF(ISERROR(E22*100/D22),"trifft nicht zu",(E22*100/D22)) -> trifft nicht zu | D22: =Bewertung!H183 -> 0 | E22: =Bewertung!G183 -> 0

Sheet Grafik
